Workbook

Sheet Resumen
B1: Frilo · URLs finales del sitio, metadatos, datos estructurados y keyword objetivo
B2: Versión del 20 de octubre de 2026. Fuente: wireframes aprobados (lienzo "Frilo — Sitio web"), Especificacion_SEO_sitio_Frilo_v2.md y Keyword research Frilo (v3), exports de Semrush del 16 y 19 de octubre de 2026, base Colombia.
B3: Decisión de URL para la app web
B4: Recomendación: el sitio de contenido ocupa https://frilo.dev y la app pasa a https://app.frilo.dev, con noindex, nofollow y fuera del sitemap. Detalle, alternativa y pasos de migración en la hoja "App y ambientes".
B5: Hojas
B6: URLs: inventario de todas las direcciones con estado, indexación, keyword objetivo, title, meta description, H1, tipo de schema y notas. Las longitudes de title y meta se calculan con fórmula y se marcan en rojo si salen del rango.
B7: Datos estructurados: el JSON-LD completo de cada URL (un solo @graph por página) con las preguntas frecuentes visibles en los wireframes. Copiar tal cual en el código.
B8: Keywords: las 106 keywords del research con su página, rol, volumen y KD. Alimenta los volúmenes de la hoja URLs y del forecast.
B9: Forecast base: clics mensuales estimados por URL en posición 10, 3 y 1, con las CTR de la hoja Supuestos. Es un techo: no descuenta AI Overviews, anuncios ni el conversor de Google.
B10: Seguimiento: hoja para llenar con datos de Search Console, Ranki y PageSpeed (indexación, posición, clics, Core Web Vitals).
B11: App y ambientes: dónde vive la app, ambiente de prueba, publicación manual, redirecciones y archivos técnicos.
B12: Cómo se eligió la keyword objetivo
... B17: Medir en Ranki las keywords sin volumen: frilo, calculadoras para independientes, guías para independientes, cesantías para independientes, dónde guardar las cesantías, qué hacer con las cesantías, glosario seguridad social, recibir dólares en colombia. Diseñar /glosario, /quienes-somos, /metodologia y /transparencia. Confirmar las rutas actuales de Términos y Política de datos en la app.

Sheet URLs
A1: ID | B1: Página | C1: URL final | D1: Ruta | E1: Tipo | F1: Wireframe | G1: Estado | H1: Meta robots | I1: En sitemap | J1: Canonical | K1: Prioridad | L1: Keyword objetivo | M1: Coincidencia con el H1 | N1: Volumen keyword objetivo | O1: KD | P1: Volumen del grupo (principal + secundarias + soporte) | Q1: Keywords secundarias | R1: Title | S1: Long. title | T1: Meta description | U1: Long. meta | V1: H1 | W1: og:type | X1: Datos estructurados | Y1: Breadcrumb | Z1: Frecuencia de actualización | AA1: Notas
A2: Home | B2: Inicio | C2: https://frilo.dev/ | D2: / | E2: Home | F2: Main.dc.html | G2: Wireframe aprobado | H2: index, follow | I2: Sí | J2: https://frilo.dev/ | K2: 1 - Alta | L2: frilo | M2: Exacta (H1 = "Frilo") | N2: =IFERROR(INDEX(Keywords!$F$2:$F$107,MATCH(L2,Keywords!$A$2:$A$107,0)),"s/d") -> s/d | O2: =IFERROR(IF(INDEX(Keywords!$G$2:$G$107,MATCH(L2,Keywords!$A$2:$A$107,0))="","s/d",INDEX(Keywords!$G$2:$G$107,MATCH(L2,Keywords!$A$2:$A$107,0))),"s/d") -> s/d | P2: =SUMIFS(Keywords!$F$2:$F$107,Keywords!$C$2:$C$107,A2,Keywords!$D$2:$D$107,"Principal")+SUMIFS(Keywords!$F$2:$F$107,Keywords!$C$2:$C$107,A2,Keywords!$D$2:$D$107,"Secundaria")+SUMIFS(Keywords!$F$2:$F$107,Keywords!$C$2:$C$107,A2,Keywords!$D$2:$D$107,"Soporte (H2/FAQ)") -> 0 | Q2: calculadoras para independientes (H2, sin datos); app para independientes (sin datos) | R2: Frilo: calculadoras de aportes y cesantías para independientes | S2: =LEN(R2) -> 62 | T2: Calcula tu planilla de independiente, aparta tu prima y tus cesantías y sigue el dólar. Gratis, en pesos o en dólares, sin registro. | U2: =IF(LEFT(T2,1)="(","",LEN(T2)) -> 132 | V2: Frilo | W2: website | X2: Organization + WebSite + Person + WebPage + FAQPage | Y2: — | Z2: Mensual | AA2: Compite por marca. El title empieza con la marca, por eso no lleva sufijo. La demanda no de marca llega por los enlaces a P01, P03 y P10. Medir "frilo" y "app para independientes" en Ranki.
A3: Hub-C | B3: Hub de calculadoras | C3: https://frilo.dev/calculadoras | D3: /calculadoras | E3: Hub | F3: CalculadorasHub.dc.html | G3: Wireframe aprobado | H3: index, follow | I3: Sí | J3: https://frilo.dev/calculadoras | K3: 2 - Media | L3: calculadoras para independientes | M3: Exacta | N3: =IFERROR(INDEX(Keywords!$F$2:$F$107,MATCH(L3,Keywords!$A$2:$A$107,0)),"s/d") -> s/d | O3: =IFERROR(IF(INDEX(Keywords!$G$2:$G$107,MATCH(L3,Keywords!$A$2:$A$107,0))="","s/d",INDEX(Keywords!$G$2:$G$107,MATCH(L3,Keywords!$A$2:$A$107,0))),"s/d") -> s/d | P3: =SUMIFS(Keywords!$F$2:$F$107,Keywords!$C$2:$C$107,A3,Keywords!$D$2:$D$107,"Principal")+SUMIFS(Keywords!$F$2:$F$107,Keywords!$C$2:$C$107,A3,Keywords!$D$2:$D$107,"Secundaria")+SUMIFS(Keywords!$F$2:$F$107,Keywords!$C$2:$C$107,A3,Keywords!$D$2:$D$107,"Soporte (H2/FAQ)") -> 0 | Q3: calculadoras para contratistas (sin datos) | R3: Calculadoras para independientes y contratistas | Frilo | S3: =LEN(R3) -> 55 | T3: Calculadoras gratis para independientes en Colombia: aportes, fecha de pago de la planilla, cesantías e intereses y dólar hoy. Sin registro. | U3: =IF(LEFT(T3,1)="(","",LEN(T3)) -> 140 | V3: Calculadoras para independientes y contratistas en Colombia | W3: website | X3: CollectionPage + ItemList + BreadcrumbList | Y3: Inicio › Calculadoras | Z3: Cuando se agregue una calculadora | AA3: Keyword sin volumen medido: incluirla en Ranki. Su rol principal es repartir autoridad a P01, P03, P05 y P10.
A4: P01 | B4: Calculadora de aportes | C4: https://frilo.dev/calculadoras/aportes-independientes | D4: /calculadoras/aportes-independientes | E4: Herramienta | F4: Calculadora.dc.html | G4: Wireframe aprobado | H4: index, follow | I4: Sí | J4: https://frilo.dev/calculadoras/aportes-independientes | K4: 1 - Alta | L4: calculadora de aportes | M4: Exacta | N4: =IFERROR(INDEX(Keywords!$F$2:$F$107,MATCH(L4,Keywords!$A$2:$A$107,0)),"s/d") -> 2400 | O4: =IFERROR(IF(INDEX(Keywords!$G$2:$G$107,MATCH(L4,Keywords!$A$2:$A$107,0))="","s/d",INDEX(Keywords!$G$2:$G$107,MATCH(L4,Keywords!$A$2:$A$107,0))),"s/d") -> 0 | P4: =SUMIFS(Keywords!$F$2:$F$107,Keywords!$C$2:$C$107,A4,Keywords!$D$2:$D$107,"Principal")+SUMIFS(Keywords!$F$2:$F$107,Keywords!$C$2:$C$107,A4,Keywords!$D$2:$D$107,"Secundaria")+SUMIFS(Keywords!$F$2:$F$107,Keywords!$C$2:$C$107,A4,Keywords!$D$2:$D$107,"Soporte (H2/FAQ)") -> 2580 | Q4: calculadora de aportes para independientes y contratistas; calculadora de aportes 2026; calculadora de liquidacion aportes en linea | R4: Calculadora de aportes para independientes 2026 | Frilo | S4: =LEN(R4) -> 55 | T4: Calcula cuánto pagas de salud, pensión, ARL y Fondo de Solidaridad como independiente o contratista en 2026. Gratis y sin registro. | U4: =IF(LEFT(T4,1)="(","",LEN(T4)) -> 131 | V4: Calculadora de aportes para independientes 2026 | W4: website | X4: WebPage + WebApplication + FAQPage + BreadcrumbList | Y4: Inicio › Calculadoras › Aportes para independientes | Z4: Anual (1.ª quincena de diciembre) y cuando cambie una norma | AA4: Pico de enero (4.400 búsquedas vs. 1.600 en meses bajos). Actualizar año y cifras antes del 15 de diciembre.
A5: P02 | B5: Guía del IBC | C5: https://frilo.dev/guias/ibc-independientes | D5: /guias/ibc-independientes | E5: Guía | F5: GuiaIBC.dc.html | G5: Wireframe aprobado | H5: index, follow | I5: Sí | J5: https://frilo.dev/guias/ibc-independientes | K5: 2 - Media | L5: ibc para independientes | M5: Exacta | N5: =IFERROR(INDEX(Keywords!$F$2:$F$107,MATCH(L5,Keywords!$A$2:$A$107,0)),"s/d") -> 90 | O5: =IFERROR(IF(INDEX(Keywords!$G$2:$G$107,MATCH(L5,Keywords!$A$2:$A$107,0))="","s/d",INDEX(Keywords!$G$2:$G$107,MATCH(L5,Keywords!$A$2:$A$107,0))),"s/d") -> 0 | P5: =SUMIFS(Keywords!$F$2:$F$107,Keywords!$C$2:$C$107,A5,Keywords!$D$2:$D$107,"Principal")+SUMIFS(Keywords!$F$2:$F$107,Keywords!$C$2:$C$107,A5,Keywords!$D$2:$D$107,"Secundaria")+SUMIFS(Keywords!$F$2:$F$107,Keywords!$C$2:$C$107,A5,Keywords!$D$2:$D$107,"Soporte (H2/FAQ)") -> 340 | Q5: calculadora ibc independientes (110, H2); como calcular el ibc para independientes 2026; como cambiar el ibc en soi para independientes | R5: IBC para independientes 2026: qué es y cómo calcularlo | Frilo | S5: =LEN(R5) -> 62 | T5: Qué es el IBC de un independiente, cómo calcularlo en 2026 con el 40% de tus ingresos y cómo cambiarlo en SOI. Con calculadora gratis. | U5: =IF(LEFT(T5,1)="(","",LEN(T5)) -> 134 | V5: IBC para independientes 2026: qué es y cómo calcularlo | W5: article | X5: Article + FAQPage + BreadcrumbList | Y5: Inicio › Guías › IBC para independientes | Z5: Anual (diciembre) | AA5: "calculadora ibc independientes" tiene más volumen (110) pero se queda como secundaria para no competir con P01, que ya calcula el IBC.
A6: P03 | B6: Calculadora de cesantías | C6: https://frilo.dev/calculadoras/cesantias | D6: /calculadoras/cesantias | E6: Herramienta | F6: Cesantias.dc.html | G6: Wireframe aprobado | H6: index, follow | I6: Sí | J6: https://frilo.dev/calculadoras/cesantias | K6: 1 - Alta | L6: calculadora de intereses de cesantías | M6: Parcial: el H1 dice "Calculadora de cesantías e intereses de cesantías" | N6: =IFERROR(INDEX(Keywords!$F$2:$F$107,MATCH(L6,Keywords!$A$2:$A$107,0)),"s/d") -> 880 | O6: =IFERROR(IF(INDEX(Keywords!$G$2:$G$107,MATCH(L6,Keywords!$A$2:$A$107,0))="","s/d",INDEX(Keywords!$G$2:$G$107,MATCH(L6,Keywords!$A$2:$A$107,0))),"s/d") -> 0 | P6: =SUMIFS(Keywords!$F$2:$F$107,Keywords!$C$2:$C$107,A6,Keywords!$D$2:$D$107,"Principal")+SUMIFS(Keywords!$F$2:$F$107,Keywords!$C$2:$C$107,A6,Keywords!$D$2:$D$107,"Secundaria")+SUMIFS(Keywords!$F$2:$F$107,Keywords!$C$2:$C$107,A6,Keywords!$D$2:$D$107,"Soporte (H2/FAQ)") -> 1130 | Q6: intereses de cesantías 2026 calculadora; calculadora de cesantías 2026; calculadora de cesantías e intereses | R6: Calculadora de cesantías e intereses de cesantías 2026 | Frilo | S6: =LEN(R6) -> 62 | T6: Calcula tus cesantías y los intereses del 12% en 2026, con contrato laboral o como independiente. Incluye años anteriores. Sin registro. | U6: =IF(LEFT(T6,1)="(","",LEN(T6)) -> 136 | V6: Calculadora de cesantías e intereses de cesantías 2026 | W6: website | X6: WebPage + WebApplication + FAQPage + BreadcrumbList | Y6: Inicio › Calculadoras › Cesantías e intereses | Z6: Anual (diciembre) | AA6: El H1 cubre "calculadora de cesantías" e "intereses de cesantías" por separado. Se mantiene: Google trata ambas formas como la misma intención y el H1 suena natural. Usar la frase exacta en el primer párrafo.
A7: P04 | B7: Descargar planilla | C7: https://frilo.dev/guias/descargar-planilla-seguridad-social | D7: /guias/descargar-planilla-seguridad-social | E7: Guía | F7: GuiaDescargarPlanilla.dc.html | G7: Wireframe aprobado | H7: index, follow | I7: Sí | J7: https://frilo.dev/guias/descargar-planilla-seguridad-social | K7: 1 - Alta | L7: descargar planilla de seguridad social | M7: Parcial: el H1 dice "Cómo descargar y verificar tu planilla de seguridad social" | N7: =IFERROR(INDEX(Keywords!$F$2:$F$107,MATCH(L7,Keywords!$A$2:$A$107,0)),"s/d") -> 1300 | O7: =IFERROR(IF(INDEX(Keywords!$G$2:$G$107,MATCH(L7,Keywords!$A$2:$A$107,0))="","s/d",INDEX(Keywords!$G$2:$G$107,MATCH(L7,Keywords!$A$2:$A$107,0))),"s/d") -> 0 | P7: =SUMIFS(Keywords!$F$2:$F$107,Keywords!$C$2:$C$107,A7,Keywords!$D$2:$D$107,"Principal")+SUMIFS(Keywords!$F$2:$F$107,Keywords!$C$2:$C$107,A7,Keywords!$D$2:$D$107,"Secundaria")+SUMIFS(Keywords!$F$2:$F$107,Keywords!$C$2:$C$107,A7,Keywords!$D$2:$D$107,"Soporte (H2/FAQ)") -> 2110 | Q7: como descargar planilla de seguridad social (390); como verificar una planilla de seguridad social (210); planilla de seguridad social independiente (210) | R7: Descargar planilla de seguridad social: paso a paso | Frilo | S7: =LEN(R7) -> 59 | T7: Descarga tu planilla de seguridad social, verifica que el pago quedó registrado y conoce qué cambia si eres independiente. Guía 2026. | U7: =IF(LEFT(T7,1)="(","",LEN(T7)) -> 133 | V7: Cómo descargar y verificar tu planilla de seguridad social | W7: article | X7: Article + FAQPage + BreadcrumbList | Y7: Inicio › Guías › Descargar la planilla | Z7: Semestral (revisar enlaces de operadores) | AA7: El title lleva la frase exacta y el H1 suma la variante "verificar" (210). Grupo informativo con mejor relación volumen/dificultad.
A8: P05 | B8: Fecha de pago de la planilla | C8: https://frilo.dev/calculadoras/fecha-pago-planilla | D8: /calculadoras/fecha-pago-planilla | E8: Herramienta | F8: FechaPago.dc.html | G8: Wireframe aprobado | H8: index, follow | I8: Sí | J8: https://frilo.dev/calculadoras/fecha-pago-planilla | K8: 2 - Media | L8: fecha de pago planilla seguridad social | M8: Parcial: el H1 dice "Fechas de pago de la planilla de seguridad social 2026" | N8: =IFERROR(INDEX(Keywords!$F$2:$F$107,MATCH(L8,Keywords!$A$2:$A$107,0)),"s/d") -> 320 | O8: =IFERROR(IF(INDEX(Keywords!$G$2:$G$107,MATCH(L8,Keywords!$A$2:$A$107,0))="","s/d",INDEX(Keywords!$G$2:$G$107,MATCH(L8,Keywords!$A$2:$A$107,0))),"s/d") -> 0 | P8: =SUMIFS(Keywords!$F$2:$F$107,Keywords!$C$2:$C$107,A8,Keywords!$D$2:$D$107,"Principal")+SUMIFS(Keywords!$F$2:$F$107,Keywords!$C$2:$C$107,A8,Keywords!$D$2:$D$107,"Secundaria")+SUMIFS(Keywords!$F$2:$F$107,Keywords!$C$2:$C$107,A8,Keywords!$D$2:$D$107,"Soporte (H2/FAQ)") -> 320 | Q8: — | R8: Fechas de pago de la planilla de seguridad social 2026 | Frilo | S8: =LEN(R8) -> 62 | T8: Consulta la fecha límite para pagar la planilla de seguridad social en 2026 según los últimos dígitos de tu documento. Calendario completo. | U8: =IF(LEFT(T8,1)="(","",LEN(T8)) -> 139 | V8: Fechas de pago de la planilla de seguridad social 2026 | W8: website | X8: WebPage + WebApplication + FAQPage + BreadcrumbList | Y8: Inicio › Calculadoras › Fecha de pago de la planilla | Z8: Anual (cargar festivos del año siguiente antes del 1-dic) | AA8: Alimenta el recordatorio de pago (registro). URL sin año.
A9: P06 | B9: Glosario: SLN | C9: https://frilo.dev/glosario/sln | D9: /glosario/sln | E9: Glosario | F9: GlosarioSLN.dc.html | G9: Wireframe aprobado (falta tabla de siglas) | H9: index, follow | I9: Sí | J9: https://frilo.dev/glosario/sln | K9: 3 - Media-baja | L9: sln en planilla de seguridad social | M9: Casi exacta: "SLN en la planilla de seguridad social" | N9: =IFERROR(INDEX(Keywords!$F$2:$F$107,MATCH(L9,Keywords!$A$2:$A$107,0)),"s/d") -> 210 | O9: =IFERROR(IF(INDEX(Keywords!$G$2:$G$107,MATCH(L9,Keywords!$A$2:$A$107,0))="","s/d",INDEX(Keywords!$G$2:$G$107,MATCH(L9,Keywords!$A$2:$A$107,0))),"s/d") -> 0 | P9: =SUMIFS(Keywords!$F$2:$F$107,Keywords!$C$2:$C$107,A9,Keywords!$D$2:$D$107,"Principal")+SUMIFS(Keywords!$F$2:$F$107,Keywords!$C$2:$C$107,A9,Keywords!$D$2:$D$107,"Secundaria")+SUMIFS(Keywords!$F$2:$F$107,Keywords!$C$2:$C$107,A9,Keywords!$D$2:$D$107,"Soporte (H2/FAQ)") -> 210 | Q9: — | R9: Qué significa SLN en la planilla de seguridad social | Frilo | S9: =LEN(R9) -> 60 | T9: Te explicamos qué significa la novedad SLN en la planilla de seguridad social, cuándo se reporta y cómo afecta tus aportes. | U9: =IF(LEFT(T9,1)="(","",LEN(T9)) -> 123 | V9: Qué significa SLN en la planilla de seguridad social | W9: article | X9: WebPage + DefinedTerm (en DefinedTermSet) + BreadcrumbList | Y9: Inicio › Glosario › SLN | Z9: Cuando cambie la resolución de la PILA | AA9: Pendiente: lista completa de siglas de novedades PILA.
A10: P07 | B10: Dólar hoy | C10: https://frilo.dev/dolar-hoy | D10: /dolar-hoy | E10: Utilidad con datos en vivo | F10: DolarHoy.dc.html | G10: Wireframe aprobado | H10: index, follow | I10: Sí | J10: https://frilo.dev/dolar-hoy | K10: 2 - Media | L10: dolar hoy colombia | M10: Exacta: "Dólar hoy en Colombia" | N10: =IFERROR(INDEX(Keywords!$F$2:$F$107,MATCH(L10,Keywords!$A$2:$A$107,0)),"s/d") -> 1000000 | O10: =IFERROR(IF(INDEX(Keywords!$G$2:$G$107,MATCH(L10,Keywords!$A$2:$A$107,0))="","s/d",INDEX(Keywords!$G$2:$G$107,MATCH(L10,Keywords!$A$2:$A$107,0))),"s/d") -> 46 | P10: =SUMIFS(Keywords!$F$2:$F$107,Keywords!$C$2:$C$107,A10,Keywords!$D$2:$D$107,"Principal")+SUMIFS(Keywords!$F$2:$F$107,Keywords!$C$2:$C$107,A10,Keywords!$D$2:$D$107,"Secundaria")+SUMIFS(Keywords!$F$2:$F$107,Keywords!$C$2:$C$107,A10,Keywords!$D$2:$D$107,"Soporte (H2/FAQ)") -> 3093600 | Q10: precio dolar hoy colombia; precio del dolar colombiano hoy; valor del dolar hoy; valor del dolar hoy colombia | R10: Dólar hoy en Colombia: precio y TRM actualizada | Frilo | S10: =LEN(R10) -> 55 | T10: Consulta el precio del dólar hoy en Colombia y la TRM oficial del día, con histórico, conversor de dólares a pesos y alertas por correo. | U10: =IF(LEFT(T10,1)="(","",LEN(T10)) -> 136 | V10: Dólar hoy en Colombia: TRM del [fecha dinámica] | W10: website | X10: WebPage + FAQPage + BreadcrumbList + Dataset (opcional) | Y10: Inicio › Dólar hoy | Z10: Diaria (revalidate 86400 s) | AA10: KD 46 a 74 y conversor de Google en la SERP: tomar la estimación de clics como techo. Página única, sin URLs por fecha.
A11: P08 | B11: Cuenta en dólares | C11: https://frilo.dev/guias/cuenta-en-dolares-colombia | D11: /guias/cuenta-en-dolares-colombia | E11: Guía comparativa | F11: GuiaCuentaDolares.dc.html | G11: Wireframe aprobado | H11: index, follow | I11: Sí | J11: https://frilo.dev/guias/cuenta-en-dolares-colombia | K11: 3 - Media-baja | L11: cuenta en dolares en colombia | M11: Exacta: "Cuenta en dólares en Colombia" | N11: =IFERROR(INDEX(Keywords!$F$2:$F$107,MATCH(L11,Keywords!$A$2:$A$107,0)),"s/d") -> 320 | O11: =IFERROR(IF(INDEX(Keywords!$G$2:$G$107,MATCH(L11,Keywords!$A$2:$A$107,0))="","s/d",INDEX(Keywords!$G$2:$G$107,MATCH(L11,Keywords!$A$2:$A$107,0))),"s/d") -> 0 | P11: =SUMIFS(Keywords!$F$2:$F$107,Keywords!$C$2:$C$107,A11,Keywords!$D$2:$D$107,"Principal")+SUMIFS(Keywords!$F$2:$F$107,Keywords!$C$2:$C$107,A11,Keywords!$D$2:$D$107,"Secundaria")+SUMIFS(Keywords!$F$2:$F$107,Keywords!$C$2:$C$107,A11,Keywords!$D$2:$D$107,"Soporte (H2/FAQ)") -> 1050 | Q11: cuenta en dolares (390); cuenta de ahorros en dolares (90); como abrir una cuenta en dolares en colombia (70) | R11: Cuenta en dólares en Colombia: opciones y requisitos | Frilo | S11: =LEN(R11) -> 60 | T11: Compara las opciones para tener una cuenta en dólares en Colombia: requisitos, costos y tiempos de apertura. Guía para freelancers en 2026. | U11: =IF(LEFT(T11,1)="(","",LEN(T11)) -> 139 | V11: Cuenta en dólares en Colombia: opciones, requisitos y costos | W11: article | X11: Article + FAQPage + BreadcrumbList | Y11: Inicio › Guías › Cuenta en dólares | Z11: Trimestral (requisitos y costos de cada entidad) | AA11: La keyword de más volumen es de marca ("cuenta en dolares bancolombia", 720): solo en la tabla, nunca en title, H1 ni URL.
A12: P09 | B12: Recibir pagos en dólares | C12: https://frilo.dev/guias/recibir-pagos-en-dolares-colombia | D12: /guias/recibir-pagos-en-dolares-colombia | E12: Guía | F12: GuiaRecibirDolares.dc.html | G12: Wireframe aprobado | H12: index, follow | I12: Sí | J12: https://frilo.dev/guias/recibir-pagos-en-dolares-colombia | K12: 2 - Media | L12: como recibir pagos en dolares en colombia | M12: Parcial: el H1 dice "Cómo recibir pagos del exterior en dólares en Colombia" | N12: =IFERROR(INDEX(Keywords!$F$2:$F$107,MATCH(L12,Keywords!$A$2:$A$107,0)),"s/d") -> 10 | O12: =IFERROR(IF(INDEX(Keywords!$G$2:$G$107,MATCH(L12,Keywords!$A$2:$A$107,0))="","s/d",INDEX(Keywords!$G$2:$G$107,MATCH(L12,Keywords!$A$2:$A$107,0))),"s/d") -> s/d | P12: =SUMIFS(Keywords!$F$2:$F$107,Keywords!$C$2:$C$107,A12,Keywords!$D$2:$D$107,"Principal")+SUMIFS(Keywords!$F$2:$F$107,Keywords!$C$2:$C$107,A12,Keywords!$D$2:$D$107,"Secundaria")+SUMIFS(Keywords!$F$2:$F$107,Keywords!$C$2:$C$107,A12,Keywords!$D$2:$D$107,"Soporte (H2/FAQ)") -> 10 | Q12: — | R12: Cómo recibir pagos del exterior en dólares en Colombia | Frilo | S12: =LEN(R12) -> 62 | T12: Recibe pagos del exterior en dólares en Colombia: opciones, costos, tiempos y qué debes declarar. Guía para freelancers e independientes. | U12: =IF(LEFT(T12,1)="(","",LEN(T12)) -> 137 | V12: Cómo recibir pagos del exterior en dólares en Colombia | W12: article | X12: Article + FAQPage + BreadcrumbList | Y12: Inicio › Guías › Recibir pagos en dólares | Z12: Trimestral | AA12: Volumen bajo (10) pero es el tema con más encaje con el perfil que cobra en dólares. Medir en Ranki "recibir pagos del exterior colombia" y "recibir dólares en colombia".
A13: P10 | B13: Calculadora de interés compuesto | C13: https://frilo.dev/calculadoras/interes-compuesto | D13: /calculadoras/interes-compuesto | E13: Herramienta | F13: InteresCompuesto.dc.html | G13: Wireframe aprobado | H13: index, follow | I13: Sí | J13: https://frilo.dev/calculadoras/interes-compuesto | K13: 1 - Alta | L13: calculadora interés compuesto | M13: Casi exacta: "Calculadora de interés compuesto" | N13: =IFERROR(INDEX(Keywords!$F$2:$F$107,MATCH(L13,Keywords!$A$2:$A$107,0)),"s/d") -> 5400 | O13: =IFERROR(IF(INDEX(Keywords!$G$2:$G$107,MATCH(L13,Keywords!$A$2:$A$107,0))="","s/d",INDEX(Keywords!$G$2:$G$107,MATCH(L13,Keywords!$A$2:$A$107,0))),"s/d") -> s/d | P13: =SUMIFS(Keywords!$F$2:$F$107,Keywords!$C$2:$C$107,A13,Keywords!$D$2:$D$107,"Principal")+SUMIFS(Keywords!$F$2:$F$107,Keywords!$C$2:$C$107,A13,Keywords!$D$2:$D$107,"Secundaria")+SUMIFS(Keywords!$F$2:$F$107,Keywords!$C$2:$C$107,A13,Keywords!$D$2:$D$107,"Soporte (H2/FAQ)") -> 5500 | Q13: simulador de ahorro (50, title); calculadora de ahorro (50) | R13: Calculadora de interés compuesto y simulador de ahorro | Frilo | S13: =LEN(R13) -> 62 | T13: Simula cuánto crece tu ahorro con interés compuesto: monto inicial, aporte mensual, tasa efectiva anual y plazo. Gratis y sin registro. | U13: =IF(LEFT(T13,1)="(","",LEN(T13)) -> 135 | V13: Calculadora de interés compuesto: simula cuánto rinde tu ahorro | W13: website | X13: WebPage + WebApplication + FAQPage + BreadcrumbList | Y13: Inicio › Calculadoras › Interés compuesto | Z13: Cuando cambien las tasas de referencia o la retención | AA13: Mayor volumen del sitio sin contar dólar hoy (5.400). La SERP no tiene un competidor colombiano con contexto local.
... A24: APP | B24: App web (herramienta) | C24: https://app.frilo.dev | D24: app.frilo.dev | E24: App web | F24: Repositorio actual de la app | G24: Existe en frilo.dev; mover | H24: noindex, nofollow (meta + cabecera X-Robots-Tag) | I24: No | J24: — (no aplica) | K24: Recomendación | L24: No aplica | M24: — | N24: =IFERROR(INDEX(Keywords!$F$2:$F$107,MATCH(L24,Keywords!$A$2:$A$107,0)),"s/d") -> s/d | O24: =IFERROR(IF(INDEX(Keywords!$G$2:$G$107,MATCH(L24,Keywords!$A$2:$A$107,0))="","s/d",INDEX(Keywords!$G$2:$G$107,MATCH(L24,Keywords!$A$2:$A$107,0))),"s/d") -> s/d | P24: =SUMIFS(Keywords!$F$2:$F$107,Keywords!$C$2:$C$107,A24,Keywords!$D$2:$D$107,"Principal")+SUMIFS(Keywords!$F$2:$F$107,Keywords!$C$2:$C$107,A24,Keywords!$D$2:$D$107,"Secundaria")+SUMIFS(Keywords!$F$2:$F$107,Keywords!$C$2:$C$107,A24,Keywords!$D$2:$D$107,"Soporte (H2/FAQ)") -> 0 | Q24: — | R24: (definido por la app) | S24: =LEN(R24) -> 21 | T24: (no aplica) | U24: =IF(LEFT(T24,1)="(","",LEN(T24)) | V24: (no aplica) | W24: — | X24: Ninguno | Y24: — | Z24: — | AA24: Ver hoja "App y ambientes". Todos los CTA "Probar la app gratis" y "Entrar" apuntan aquí.
A26: Rangos: title de 55 a 65 caracteres con " | Frilo"; meta description de 120 a 150. Verde = en rango; rojo = fuera de rango en una página indexable (las legales se aceptan cortas). El año va en title y H1, nunca en la URL.

Sheet Datos estructurados
A1: ID | B1: URL final | C1: Tipos | D1: JSON-LD para <script type="application/ld+json"> | E1: Notas
A2: Home | B2: =URLs!C2 -> https://frilo.dev/ | C2: Organization + WebSite + Person + WebPage + FAQPage | D2: { "@context": "https://schema.org", "@graph": [ { "@type": "Organization", "@id": "https://frilo.dev/#organization", "name": "Frilo", "url": "https://frilo.dev", "logo": "https://frilo.dev/logos/isotipo-oliva.png", "slogan": "Tus finanzas, mejor con Frilo", "areaServed": "CO" }, { "@type": "WebSite", "@id": "https://frilo.dev/#website", "url": "https://frilo.dev", "name": "Frilo", "inLanguage": "es-CO", "publisher": { "@id": "https://frilo.dev/#organization" } }, { "@type": "Person", "@id": "https://frilo.dev/#nicolas", "name": "Nicolás Suárez", "jobTitle": "Fundador de Frilo", "url": "https://frilo.dev/quienes-somos" }, { "@type": "WebPage", "@id": "https://frilo.dev", "url": "https://frilo.dev", "name": "Frilo", "description": "Calcula tu planilla de independiente, aparta tu prima y tus cesantías y sigue el dólar. Gratis, en pesos o en dólares, sin registro.", "inLanguage": "es-CO", "isPartOf": { "@id": "https://frilo.dev/#website" }, "dateModified": "2026-10-20" }, { "@type": "FAQPage", "@id": "https://frilo.dev/#faq", "mainEntity": [ { "@type": "Question", "name": "¿Frilo es gratis?", "acceptedAnswer": { "@type": "Answer", "text": "Sí. Las calculadoras se usan sin registro. Crear una cuenta es gratis y sirve para guardar tus cálculos y recibir alertas." } }, { "@type": "Question", "name": "¿Las cuentas que recomienda Frilo le pagan?", "acceptedAnswer": { "@type": "Answer", "text": "No. Frilo es un proyecto nuevo y gratuito: ninguna entidad nos paga por aparecer y el orden de las comparativas es siempre por tasa. No vendemos tus datos." } }, { "@type": "Question", "name": "¿Frilo paga mi planilla?", "acceptedAnswer": { "@type": "Answer", "text": "No. Calcula el valor y te lleva al operador para que la pagues tú." } }, { "@type": "Question", "name": "¿Sirve si me pagan en pesos?", "acceptedAnswer": { "@type": "Answer", "text": "Sí. Funciona para contratos de prestación de servicios en pesos, en dólares o de ambas formas." } }, { "@type": "Question", "name": "¿De dónde sale la TRM?", "acceptedAnswer": { "@type": "Answer", "text": "Del dato oficial que publica la Superintendencia Financiera en Datos Abiertos Colombia." } }, { "@type": "Question", "name": "¿Es asesoría financiera?", "acceptedAnswer": { "@type": "Answer", "text": "No. Son cálculos y simulaciones con fines informativos." } } ] } ] } | E2: Un solo script por página. Organization, WebSite y Person van en todas las páginas con el mismo @id. dateModified y lastReviewed = fecha real de la última edición (la misma visible en la página). FAQPage con las preguntas visibles del wireframe: si el texto cambia en el código, regenerar.
A3: Hub-C | B3: =URLs!C3 -> https://frilo.dev/calculadoras | C3: CollectionPage + ItemList + BreadcrumbList | D3: { "@context": "https://schema.org", "@graph": [ { "@type": "Organization", "@id": "https://frilo.dev/#organization", "name": "Frilo", "url": "https://frilo.dev", "logo": "https://frilo.dev/logos/isotipo-oliva.png", "slogan": "Tus finanzas, mejor con Frilo", "areaServed": "CO" }, { "@type": "WebSite", "@id": "https://frilo.dev/#website", "url": "https://frilo.dev", "name": "Frilo", "inLanguage": "es-CO", "publisher": { "@id": "https://frilo.dev/#organization" } }, { "@type": "Person", "@id": "https://frilo.dev/#nicolas", "name": "Nicolás Suárez", "jobTitle": "Fundador de Frilo", "url": "https://frilo.dev/quienes-somos" }, { "@type": "CollectionPage", "@id": "https://frilo.dev/calculadoras", "url": "https://frilo.dev/calculadoras", "name": "Calculadoras para independientes y contratistas en Colombia", "description": "Calculadoras gratis para independientes en Colombia: aportes, fecha de pago de la planilla, cesantías e intereses y dólar hoy. Sin registro.", "inLanguage": "es-CO", "isPartOf": { "@id": "https://frilo.dev/#website" }, "dateModified": "2026-10-20", "mainEntity": { "@type": "ItemList", "itemListElement": [ { "@type": "ListItem", "position": 1, "url": "https://frilo.dev/calculadoras/aportes-independientes", "name": "Calculadora de aportes para independientes 2026" }, { "@type": "ListItem", "position": 2, "url": "https://frilo.dev/calculadoras/fecha-pago-planilla", "name": "Fechas de pago de la planilla de seguridad social 2026" }, { "@type": "ListItem", "position": 3, "url": "https://frilo.dev/calculadoras/cesantias", "name": "Calculadora de cesantías e intereses de cesantías 2026" }, { "@type": "ListItem", "position": 4, "url": "https://frilo.dev/calculadoras/interes-compuesto", "name": "Calculadora de interés compuesto: simula cuánto rinde tu ahorro" }, { "@type": "ListItem", "position": 5, "url": "https://frilo.dev/dolar-hoy", "name": "Dólar hoy en Colombia: TRM del [fecha dinámica]" } ] } }, { "@type": "BreadcrumbList", "itemListElement": [ { "@type": "ListItem", "position": 1, "name": "Inicio", "item": "https://frilo.dev" }, { "@type": "ListItem", "position": 2, "name": "Calculadoras" } ] } ] } | E3: Un solo script por página. Organization, WebSite y Person van en todas las páginas con el mismo @id. dateModified y lastReviewed = fecha real de la última edición (la misma visible en la página). FAQPage con las preguntas visibles del wireframe: si el texto cambia en el código, regenerar.
A4: P01 | B4: =URLs!C4 -> https://frilo.dev/calculadoras/aportes-independientes | C4: WebPage + WebApplication + FAQPage + BreadcrumbList | D4: { "@context": "https://schema.org", "@graph": [ { "@type": "Organization", "@id": "https://frilo.dev/#organization", "name": "Frilo", "url": "https://frilo.dev", "logo": "https://frilo.dev/logos/isotipo-oliva.png", "slogan": "Tus finanzas, mejor con Frilo", "areaServed": "CO" }, { "@type": "WebSite", "@id": "https://frilo.dev/#website", "url": "https://frilo.dev", "name": "Frilo", "inLanguage": "es-CO", "publisher": { "@id": "https://frilo.dev/#organization" } }, { "@type": "Person", "@id": "https://frilo.dev/#nicolas", "name": "Nicolás Suárez", "jobTitle": "Fundador de Frilo", "url": "https://frilo.dev/quienes-somos" }, { "@type": "WebPage", "@id": "https://frilo.dev/calculadoras/aportes-independientes", "url": "https://frilo.dev/calculadoras/aportes-independientes", "name": "Calculadora de aportes para independientes 2026", "description": "Calcula cuánto pagas de salud, pensión, ARL y Fondo de Solidaridad como independiente o contratista en 2026. Gratis y sin registro.", "inLanguage": "es-CO", "isPartOf": { "@id": "https://frilo.dev/#website" }, "dateModified": "2026-10-20", "mainEntity": { "@id": "https://frilo.dev/calculadoras/aportes-independientes#app" }, "author": { "@id": "https://frilo.dev/#nicolas" }, "reviewedBy": { "@type": "Organization", "name": "Equipo de finanzas Frilo", "parentOrganization": { "@id": "https://frilo.dev/#organization" } }, "lastReviewed": "2026-10-20" }, { "@type": "WebApplication", "@id": "https://frilo.dev/calculadoras/aportes-independientes#app", "name": "Calculadora de aportes para independientes 2026", "url": "https://frilo.dev/calculadoras/aportes-independientes", "applicationCategory": "FinanceApplication", "operatingSystem": "Web", "inLanguage": "es-CO", "isAccessibleForFree": true, "offers": { "@type": "Offer", "price": "0", "priceCurrency": "COP" }, "publisher": { "@id": "https://frilo.dev/#organization" }, "dateModified": "2026-10-20" }, { "@type": "BreadcrumbList", "itemListElement": [ { "@type": "ListItem", "position": 1, "name": "Inicio", "item": "https://frilo.dev" }, { "@type": "ListItem", "position": 2, "name": "Calculadoras", "item": "https://frilo.dev/calculadoras" }, { "@type": "ListItem", "position": 3, "name": "Aportes para independientes" } ] }, { "@type": "FAQPage", "@id": "https://frilo.dev/calculadoras/aportes-independientes#faq", "mainEntity": [ { "@type": "Question", "name": "¿Puedo calcular la liquidación de mi planilla antes de pagar?", "acceptedAnswer": { "@type": "Answer", "text": "Sí. Esta calculadora hace la liquidación de aportes con las tarifas y el redondeo de la PILA. El valor final lo confirma el operador al liquidar tu planilla." } }, { "@type": "Question", "name": "¿El resultado es el mismo que me da Mi Planilla o SOI?", "acceptedAnswer": { "@type": "Answer", "text": "Usamos la misma fórmula (40% del ingreso, tarifas de 2026 y redondeo a 100). Puede haber diferencias si reportas novedades, días incompletos o una clase de riesgo distinta." } }, { "@type": "Question", "name": "¿Tengo que pagar ARL si trabajo desde mi casa?", "acceptedAnswer": { "@type": "Answer", "text": "Depende de tu contrato. Si tienes un contrato de prestación de servicios de más de un mes, la ARL es obligatoria (Decreto 723 de 2013): en riesgo I a III la pagas tú y en IV y V la paga el contratante. Si trabajas por tu cuenta, sin contrato, en riesgo I a III es voluntaria." } }, { "@type": "Question", "name": "¿Qué pasa si facturo menos de un salario mínimo?", "acceptedAnswer": { "@type": "Answer", "text": "Cotizas igual sobre un salario mínimo ($1.750.905 en 2026), porque es la base mínima de cotización. Por eso la calculadora nunca usa un IBC menor." } }, { "@type": "Question", "name": "¿Cómo cotizo si tengo varios contratos?", "acceptedAnswer": { "@type": "Answer", "text": "Sumas lo que facturas en el mes por todos tus contratos y sacas el 40% de esa suma. El IBC sigue con el tope de 25 salarios mínimos." } }, { "@type": "Question", "name": "¿Si me pagan en dólares, qué TRM uso?", "acceptedAnswer": { "@type": "Answer", "text": "Usa el valor en pesos de lo que recibiste. Si necesitas convertir, toma la TRM del día en que te pagaron. Puedes consultarla en dólar hoy en Colombia." } }, { "@type": "Question", "name": "¿Y si trabajo por cuenta propia, sin contrato de prestación de servicios?", "acceptedAnswer": { "@type": "Answer", "text": "Desde el Decreto 379 de 2026, primero descuentas tus costos (o aplicas la presunción de costos de la UGPP) y sacas el 40% del ingreso neto. Esta calculadora está pensada para contratistas de prestación de servicios." } } ] } ] } | E4: Un solo script por página. Organization, WebSite y Person van en todas las páginas con el mismo @id. dateModified y lastReviewed = fecha real de la última edición (la misma visible en la página). FAQPage con las preguntas visibles del wireframe: si el texto cambia en el código, regenerar.
A5: P02 | B5: =URLs!C5 -> https://frilo.dev/guias/ibc-independientes | C5: Article + FAQPage + BreadcrumbList | D5: { "@context": "https://schema.org", "@graph": [ { "@type": "Organization", "@id": "https://frilo.dev/#organization", "name": "Frilo", "url": "https://frilo.dev", "logo": "https://frilo.dev/logos/isotipo-oliva.png", "slogan": "Tus finanzas, mejor con Frilo", "areaServed": "CO" }, { "@type": "WebSite", "@id": "https://frilo.dev/#website", "url": "https://frilo.dev", "name": "Frilo", "inLanguage": "es-CO", "publisher": { "@id": "https://frilo.dev/#organization" } }, { "@type": "Person", "@id": "https://frilo.dev/#nicolas", "name": "Nicolás Suárez", "jobTitle": "Fundador de Frilo", "url": "https://frilo.dev/quienes-somos" }, { "@type": "WebPage", "@id": "https://frilo.dev/guias/ibc-independientes", "url": "https://frilo.dev/guias/ibc-independientes", "name": "IBC para independientes 2026: qué es y cómo calcularlo", "description": "Qué es el IBC de un independiente, cómo calcularlo en 2026 con el 40% de tus ingresos y cómo cambiarlo en SOI. Con calculadora gratis.", "inLanguage": "es-CO", "isPartOf": { "@id": "https://frilo.dev/#website" }, "dateModified": "2026-10-20", "reviewedBy": { "@type": "Organization", "name": "Equipo de finanzas Frilo", "parentOrganization": { "@id": "https://frilo.dev/#organization" } }, "lastReviewed": "2026-10-20", "mainEntity": { "@id": "https://frilo.dev/guias/ibc-independientes#article" } }, { "@type": "Article", "@id": "https://frilo.dev/guias/ibc-independientes#article", "headline": "IBC para independientes 2026: qué es y cómo calcularlo", "description": "Qué es el IBC de un independiente, cómo calcularlo en 2026 con el 40% de tus ingresos y cómo cambiarlo en SOI. Con calculadora gratis.", "mainEntityOfPage": "https://frilo.dev/guias/ibc-independientes", "inLanguage": "es-CO", "author": { "@id": "https://frilo.dev/#nicolas" }, "publisher": { "@id": "https://frilo.dev/#organization" }, "datePublished": "2026-10-20", "dateModified": "2026-10-20", "image": "https://frilo.dev/og/guias/ibc-independientes.png" }, { "@type": "BreadcrumbList", "itemListElement": [ { "@type": "ListItem", "position": 1, "name": "Inicio", "item": "https://frilo.dev" }, { "@type": "ListItem", "position": 2, "name": "Guías", "item": "https://frilo.dev/guias" }, { "@type": "ListItem", "position": 3, "name": "IBC para independientes" } ] }, { "@type": "FAQPage", "@id": "https://frilo.dev/guias/ibc-independientes#faq", "mainEntity": [ { "@type": "Question", "name": "¿El IBC se calcula sobre lo facturado o sobre lo recibido?", "acceptedAnswer": { "@type": "Answer", "text": "Si tienes contrato de prestación de servicios, sobre el 40% del valor mensualizado del contrato, sin IVA. Como cotizas mes vencido, pagas en la planilla del mes siguiente. Si trabajas por cuenta propia, sin contrato de prestación de servicios, primero descuentas tus costos y sacas el 40% del ingreso neto (Decreto 379 de 2026)." } }, { "@type": "Question", "name": "¿Puedo cotizar sobre un IBC mayor al 40%?", "acceptedAnswer": { "@type": "Answer", "text": "Sí. El 40% es la base mínima, no la máxima (artículo 89 de la Ley 2277 de 2022). Puedes cotizar sobre más para mejorar tu pensión futura, sin pasar de 25 salarios mínimos ($43.772.625 en 2026)." } }, { "@type": "Question", "name": "¿Qué pasa si no reporto bien mi IBC?", "acceptedAnswer": { "@type": "Answer", "text": "La UGPP fiscaliza los aportes de los independientes y puede cobrar lo que faltó, con intereses y sanciones. Guarda tus facturas y las planillas pagadas." } } ] } ] } | E5: Un solo script por página. Organization, WebSite y Person van en todas las páginas con el mismo @id. dateModified y lastReviewed = fecha real de la última edición (la misma visible en la página). FAQPage con las preguntas visibles del wireframe: si el texto cambia en el código, regenerar.
A6: P03 | B6: =URLs!C6 -> https://frilo.dev/calculadoras/cesantias | C6: WebPage + WebApplication + FAQPage + BreadcrumbList | D6: { "@context": "https://schema.org", "@graph": [ { "@type": "Organization", "@id": "https://frilo.dev/#organization", "name": "Frilo", "url": "https://frilo.dev", "logo": "https://frilo.dev/logos/isotipo-oliva.png", "slogan": "Tus finanzas, mejor con Frilo", "areaServed": "CO" }, { "@type": "WebSite", "@id": "https://frilo.dev/#website", "url": "https://frilo.dev", "name": "Frilo", "inLanguage": "es-CO", "publisher": { "@id": "https://frilo.dev/#organization" } }, { "@type": "Person", "@id": "https://frilo.dev/#nicolas", "name": "Nicolás Suárez", "jobTitle": "Fundador de Frilo", "url": "https://frilo.dev/quienes-somos" }, { "@type": "WebPage", "@id": "https://frilo.dev/calculadoras/cesantias", "url": "https://frilo.dev/calculadoras/cesantias", "name": "Calculadora de cesantías e intereses de cesantías 2026", "description": "Calcula tus cesantías y los intereses del 12% en 2026, con contrato laboral o como independiente. Incluye años anteriores. Sin registro.", "inLanguage": "es-CO", "isPartOf": { "@id": "https://frilo.dev/#website" }, "dateModified": "2026-10-20", "mainEntity": { "@id": "https://frilo.dev/calculadoras/cesantias#app" }, "author": { "@id": "https://frilo.dev/#nicolas" }, "reviewedBy": { "@type": "Organization", "name": "Equipo de finanzas Frilo", "parentOrganization": { "@id": "https://frilo.dev/#organization" } }, "lastReviewed": "2026-10-20" }, { "@type": "WebApplication", "@id": "https://frilo.dev/calculadoras/cesantias#app", "name": "Calculadora de cesantías e intereses de cesantías 2026", "url": "https://frilo.dev/calculadoras/cesantias", "applicationCategory": "FinanceApplication", "operatingSystem": "Web", "inLanguage": "es-CO", "isAccessibleForFree": true, "offers": { "@type": "Offer", "price": "0", "priceCurrency": "COP" }, "publisher": { "@id": "https://frilo.dev/#organization" }, "dateModified": "2026-10-20" }, { "@type": "BreadcrumbList", "itemListElement": [ { "@type": "ListItem", "position": 1, "name": "Inicio", "item": "https://frilo.dev" }, { "@type": "ListItem", "position": 2, "name": "Calculadoras", "item": "https://frilo.dev/calculadoras" }, { "@type": "ListItem", "position": 3, "name": "Cesantías e intereses" } ] }, { "@type": "FAQPage", "@id": "https://frilo.dev/calculadoras/cesantias#faq", "mainEntity": [ { "@type": "Question", "name": "¿Cuándo pagan los intereses de cesantías en 2026?", "acceptedAnswer": { "@type": "Answer", "text": "Los intereses de las cesantías de 2025 se pagan directamente al trabajador a más tardar el 31 de enero de 2026. Las cesantías se consignan al fondo a más tardar el 14 de febrero." } }, { "@type": "Question", "name": "¿Qué pasa si el empleador no consigna las cesantías a tiempo?", "acceptedAnswer": { "@type": "Answer", "text": "Debe pagar una sanción moratoria: un día de salario por cada día de retraso en la consignación (Ley 50 de 1990, artículo 99)." } }, { "@type": "Question", "name": "¿El auxilio de transporte se incluye en las cesantías?", "acceptedAnswer": { "@type": "Answer", "text": "Sí. Si ganas hasta 2 salarios mínimos y tienes derecho al auxilio de transporte ($249.095 en 2026), se suma al salario para liquidar las cesantías y sus intereses." } }, { "@type": "Question", "name": "¿Un independiente tiene derecho a cesantías?", "acceptedAnswer": { "@type": "Answer", "text": "No por su contrato. Puede crear las suyas apartando el 8,33% de cada pago. Ver la guía." } } ] } ] } | E6: Un solo script por página. Organization, WebSite y Person van en todas las páginas con el mismo @id. dateModified y lastReviewed = fecha real de la última edición (la misma visible en la página). FAQPage con las preguntas visibles del wireframe: si el texto cambia en el código, regenerar.
A7: P04 | B7: =URLs!C7 -> https://frilo.dev/guias/descargar-planilla-seguridad-social | C7: Article + FAQPage + BreadcrumbList | D7: { "@context": "https://schema.org", "@graph": [ { "@type": "Organization", "@id": "https://frilo.dev/#organization", "name": "Frilo", "url": "https://frilo.dev", "logo": "https://frilo.dev/logos/isotipo-oliva.png", "slogan": "Tus finanzas, mejor con Frilo", "areaServed": "CO" }, { "@type": "WebSite", "@id": "https://frilo.dev/#website", "url": "https://frilo.dev", "name": "Frilo", "inLanguage": "es-CO", "publisher": { "@id": "https://frilo.dev/#organization" } }, { "@type": "Person", "@id": "https://frilo.dev/#nicolas", "name": "Nicolás Suárez", "jobTitle": "Fundador de Frilo", "url": "https://frilo.dev/quienes-somos" }, { "@type": "WebPage", "@id": "https://frilo.dev/guias/descargar-planilla-seguridad-social", "url": "https://frilo.dev/guias/descargar-planilla-seguridad-social", "name": "Cómo descargar y verificar tu planilla de seguridad social", "description": "Descarga tu planilla de seguridad social, verifica que el pago quedó registrado y conoce qué cambia si eres independiente. Guía 2026.", "inLanguage": "es-CO", "isPartOf": { "@id": "https://frilo.dev/#website" }, "dateModified": "2026-10-20", "reviewedBy": { "@type": "Organization", "name": "Equipo de finanzas Frilo", "parentOrganization": { "@id": "https://frilo.dev/#organization" } }, "lastReviewed": "2026-10-20", "mainEntity": { "@id": "https://frilo.dev/guias/descargar-planilla-seguridad-social#article" } }, { "@type": "Article", "@id": "https://frilo.dev/guias/descargar-planilla-seguridad-social#article", "headline": "Cómo descargar y verificar tu planilla de seguridad social", "description": "Descarga tu planilla de seguridad social, verifica que el pago quedó registrado y conoce qué cambia si eres independiente. Guía 2026.", "mainEntityOfPage": "https://frilo.dev/guias/descargar-planilla-seguridad-social", "inLanguage": "es-CO", "author": { "@id": "https://frilo.dev/#nicolas" }, "publisher": { "@id": "https://frilo.dev/#organization" }, "datePublished": "2026-10-20", "dateModified": "2026-10-20", "image": "https://frilo.dev/og/guias/descargar-planilla-seguridad-social.png" }, { "@type": "BreadcrumbList", "itemListElement": [ { "@type": "ListItem", "position": 1, "name": "Inicio", "item": "https://frilo.dev" }, { "@type": "ListItem", "position": 2, "name": "Guías", "item": "https://frilo.dev/guias" }, { "@type": "ListItem", "position": 3, "name": "Descargar la planilla" } ] }, { "@type": "FAQPage", "@id": "https://frilo.dev/guias/descargar-planilla-seguridad-social#faq", "mainEntity": [ { "@type": "Question", "name": "¿Puedo descargar la planilla si pagué en otro operador?", "acceptedAnswer": { "@type": "Answer", "text": "No. Cada operador guarda solo las planillas que se pagaron con él. Entra al portal del operador donde hiciste el pago." } }, { "@type": "Question", "name": "¿Cuánto tarda en aparecer el pago?", "acceptedAnswer": { "@type": "Answer", "text": "Depende del operador y del medio de pago. Si no aparece, revisa con el número de planilla en el portal del operador o comunícate con su línea de atención." } }, { "@type": "Question", "name": "¿La planilla sirve como certificado para mi contratante?", "acceptedAnswer": { "@type": "Answer", "text": "Sí. Los contratantes suelen pedir la planilla pagada del periodo para pagar tus honorarios, porque deben verificar que cotizaste." } } ] } ] } | E7: Un solo script por página. Organization, WebSite y Person van en todas las páginas con el mismo @id. dateModified y lastReviewed = fecha real de la última edición (la misma visible en la página). FAQPage con las preguntas visibles del wireframe: si el texto cambia en el código, regenerar.
A8: P05 | B8: =URLs!C8 -> https://frilo.dev/calculadoras/fecha-pago-planilla | C8: WebPage + WebApplication + FAQPage + BreadcrumbList | D8: { "@context": "https://schema.org", "@graph": [ { "@type": "Organization", "@id": "https://frilo.dev/#organization", "name": "Frilo", "url": "https://frilo.dev", "logo": "https://frilo.dev/logos/isotipo-oliva.png", "slogan": "Tus finanzas, mejor con Frilo", "areaServed": "CO" }, { "@type": "WebSite", "@id": "https://frilo.dev/#website", "url": "https://frilo.dev", "name": "Frilo", "inLanguage": "es-CO", "publisher": { "@id": "https://frilo.dev/#organization" } }, { "@type": "Person", "@id": "https://frilo.dev/#nicolas", "name": "Nicolás Suárez", "jobTitle": "Fundador de Frilo", "url": "https://frilo.dev/quienes-somos" }, { "@type": "WebPage", "@id": "https://frilo.dev/calculadoras/fecha-pago-planilla", "url": "https://frilo.dev/calculadoras/fecha-pago-planilla", "name": "Fechas de pago de la planilla de seguridad social 2026", "description": "Consulta la fecha límite para pagar la planilla de seguridad social en 2026 según los últimos dígitos de tu documento. Calendario completo.", "inLanguage": "es-CO", "isPartOf": { "@id": "https://frilo.dev/#website" }, "dateModified": "2026-10-20", "mainEntity": { "@id": "https://frilo.dev/calculadoras/fecha-pago-planilla#app" }, "author": { "@id": "https://frilo.dev/#nicolas" }, "reviewedBy": { "@type": "Organization", "name": "Equipo de finanzas Frilo", "parentOrganization": { "@id": "https://frilo.dev/#organization" } }, "lastReviewed": "2026-10-20" }, { "@type": "WebApplication", "@id": "https://frilo.dev/calculadoras/fecha-pago-planilla#app", "name": "Fechas de pago de la planilla de seguridad social 2026", "url": "https://frilo.dev/calculadoras/fecha-pago-planilla", "applicationCategory": "FinanceApplication", "operatingSystem": "Web", "inLanguage": "es-CO", "isAccessibleForFree": true, "offers": { "@type": "Offer", "price": "0", "priceCurrency": "COP" }, "publisher": { "@id": "https://frilo.dev/#organization" }, "dateModified": "2026-10-20" }, { "@type": "BreadcrumbList", "itemListElement": [ { "@type": "ListItem", "position": 1, "name": "Inicio", "item": "https://frilo.dev" }, { "@type": "ListItem", "position": 2, "name": "Calculadoras", "item": "https://frilo.dev/calculadoras" }, { "@type": "ListItem", "position": 3, "name": "Fecha de pago de la planilla" } ] }, { "@type": "FAQPage", "@id": "https://frilo.dev/calculadoras/fecha-pago-planilla#faq", "mainEntity": [ { "@type": "Question", "name": "¿Qué pasa si la fecha cae en festivo?", "acceptedAnswer": { "@type": "Answer", "text": "No puede caer en festivo: el plazo se cuenta en días hábiles, así que los sábados, domingos y festivos no cuentan. Por eso tu fecha cambia de un mes a otro aunque tus dígitos sean los mismos." } }, { "@type": "Question", "name": "¿Uso los dígitos de la cédula o del NIT?", "acceptedAnswer": { "@type": "Answer", "text": "Los dos últimos dígitos del documento con el que pagas la planilla. Si pagas con tu NIT, toma los dos últimos dígitos incluyendo el dígito de verificación." } }, { "@type": "Question", "name": "¿Puedo pagar antes de mi fecha?", "acceptedAnswer": { "@type": "Answer", "text": "Sí. La fecha es el límite, no el único día posible. Puedes pagar desde que el operador habilita el periodo." } }, { "@type": "Question", "name": "¿Frilo me puede avisar cada mes?", "acceptedAnswer": { "@type": "Answer", "text": "Sí. Crea tu cuenta gratis, escribe los dos últimos dígitos de tu documento y te enviamos un correo 3 días hábiles antes y el mismo día de tu fecha límite." } } ] } ] } | E8: Un solo script por página. Organization, WebSite y Person van en todas las páginas con el mismo @id. dateModified y lastReviewed = fecha real de la última edición (la misma visible en la página). FAQPage con las preguntas visibles del wireframe: si el texto cambia en el código, regenerar.
A9: P06 | B9: =URLs!C9 -> https://frilo.dev/glosario/sln | C9: WebPage + DefinedTerm (en DefinedTermSet) + BreadcrumbList | D9: { "@context": "https://schema.org", "@graph": [ { "@type": "Organization", "@id": "https://frilo.dev/#organization", "name": "Frilo", "url": "https://frilo.dev", "logo": "https://frilo.dev/logos/isotipo-oliva.png", "slogan": "Tus finanzas, mejor con Frilo", "areaServed": "CO" }, { "@type": "WebSite", "@id": "https://frilo.dev/#website", "url": "https://frilo.dev", "name": "Frilo", "inLanguage": "es-CO", "publisher": { "@id": "https://frilo.dev/#organization" } }, { "@type": "Person", "@id": "https://frilo.dev/#nicolas", "name": "Nicolás Suárez", "jobTitle": "Fundador de Frilo", "url": "https://frilo.dev/quienes-somos" }, { "@type": "WebPage", "@id": "https://frilo.dev/glosario/sln", "url": "https://frilo.dev/glosario/sln", "name": "Qué significa SLN en la planilla de seguridad social", "description": "Te explicamos qué significa la novedad SLN en la planilla de seguridad social, cuándo se reporta y cómo afecta tus aportes.", "inLanguage": "es-CO", "isPartOf": { "@id": "https://frilo.dev/#website" }, "dateModified": "2026-10-20", "author": { "@id": "https://frilo.dev/#nicolas" }, "reviewedBy": { "@type": "Organization", "name": "Equipo de finanzas Frilo", "parentOrganization": { "@id": "https://frilo.dev/#organization" } }, "lastReviewed": "2026-10-20", "mainEntity": { "@id": "https://frilo.dev/glosario/sln#term" } }, { "@type": "DefinedTerm", "@id": "https://frilo.dev/glosario/sln#term", "name": "SLN", "alternateName": "Suspensión temporal del contrato o licencia no remunerada", "description": "[Primera oración visible de la página]", "inDefinedTermSet": { "@type": "DefinedTermSet", "@id": "https://frilo.dev/glosario", "name": "Glosario de seguridad social para independientes" } }, { "@type": "BreadcrumbList", "itemListElement": [ { "@type": "ListItem", "position": 1, "name": "Inicio", "item": "https://frilo.dev" }, { "@type": "ListItem", "position": 2, "name": "Glosario", "item": "https://frilo.dev/glosario" }, { "@type": "ListItem", "position": 3, "name": "SLN" } ] } ] } | E9: Un solo script por página. Organization, WebSite y Person van en todas las páginas con el mismo @id. dateModified y lastReviewed = fecha real de la última edición (la misma visible en la página). FAQPage con las preguntas visibles del wireframe: si el texto cambia en el código, regenerar. description = primera oración visible.
A10: P07 | B10: =URLs!C10 -> https://frilo.dev/dolar-hoy | C10: WebPage + FAQPage + BreadcrumbList + Dataset (opcional) | D10: { "@context": "https://schema.org", "@graph": [ { "@type": "Organization", "@id": "https://frilo.dev/#organization", "name": "Frilo", "url": "https://frilo.dev", "logo": "https://frilo.dev/logos/isotipo-oliva.png", "slogan": "Tus finanzas, mejor con Frilo", "areaServed": "CO" }, { "@type": "WebSite", "@id": "https://frilo.dev/#website", "url": "https://frilo.dev", "name": "Frilo", "inLanguage": "es-CO", "publisher": { "@id": "https://frilo.dev/#organization" } }, { "@type": "Person", "@id": "https://frilo.dev/#nicolas", "name": "Nicolás Suárez", "jobTitle": "Fundador de Frilo", "url": "https://frilo.dev/quienes-somos" }, { "@type": "WebPage", "@id": "https://frilo.dev/dolar-hoy", "url": "https://frilo.dev/dolar-hoy", "name": "Dólar hoy en Colombia: TRM del [fecha dinámica]", "description": "Consulta el precio del dólar hoy en Colombia y la TRM oficial del día, con histórico, conversor de dólares a pesos y alertas por correo.", "inLanguage": "es-CO", "isPartOf": { "@id": "https://frilo.dev/#website" }, "dateModified": "2026-10-20", "author": { "@id": "https://frilo.dev/#nicolas" }, "reviewedBy": { "@type": "Organization", "name": "Equipo de finanzas Frilo", "parentOrganization": { "@id": "https://frilo.dev/#organization" } } }, { "@type": "Dataset", "name": "TRM de los últimos 30 días", "description": "Tasa Representativa del Mercado (pesos por dólar) certificada por la Superintendencia Financiera de Colombia.", "creator": { "@type": "GovernmentOrganization", "name": "Superintendencia Financiera de Colombia" }, "distribution": { "@type": "DataDownload", "encodingFormat": "application/json", "contentUrl": "https://www.datos.gov.co/resource/32sa-8pi3.json" }, "temporalCoverage": "[últimos 30 días, dinámico]", "dateModified": "[fecha de la TRM, dinámica]" }, { "@type": "BreadcrumbList", "itemListElement": [ { "@type": "ListItem", "position": 1, "name": "Inicio", "item": "https://frilo.dev" }, { "@type": "ListItem", "position": 2, "name": "Dólar hoy" } ] }, { "@type": "FAQPage", "@id": "https://frilo.dev/dolar-hoy#faq", "mainEntity": [ { "@type": "Question", "name": "¿A cómo está el dólar en Colombia hoy?", "acceptedAnswer": { "@type": "Answer", "text": "Hoy la TRM está en [X.XXX,XX] pesos por dólar, vigente desde el [fecha]." } }, { "@type": "Question", "name": "¿La TRM es el precio al que me compran los dólares?", "acceptedAnswer": { "@type": "Answer", "text": "No exactamente. La TRM es la referencia oficial. Bancos y plataformas compran tus dólares con su propia tasa, normalmente por debajo de la TRM, y pueden cobrar comisión." } }, { "@type": "Question", "name": "¿Qué TRM uso para calcular mi planilla si me pagan en dólares?", "acceptedAnswer": { "@type": "Answer", "text": "Cotizas sobre el valor en pesos que recibiste. Para estimarlo, usa la TRM del día del pago y la calculadora de aportes." } }, { "@type": "Question", "name": "¿Necesito una cuenta en dólares para recibir pagos del exterior?", "acceptedAnswer": { "@type": "Answer", "text": "No. Puedes recibirlos en tu cuenta en pesos, y el banco los convierte. Una cuenta en dólares te deja elegir cuándo cambiarlos. Compara opciones en cuenta en dólares en Colombia." } } ] } ] } | E10: Un solo script por página. Organization, WebSite y Person van en todas las páginas con el mismo @id. dateModified y lastReviewed = fecha real de la última edición (la misma visible en la página). FAQPage con las preguntas visibles del wireframe: si el texto cambia en el código, regenerar. La FAQ "¿A cómo está el dólar…" y el Dataset llevan valores dinámicos.
A11: P08 | B11: =URLs!C11 -> https://frilo.dev/guias/cuenta-en-dolares-colombia | C11: Article + FAQPage + BreadcrumbList | D11: { "@context": "https://schema.org", "@graph": [ { "@type": "Organization", "@id": "https://frilo.dev/#organization", "name": "Frilo", "url": "https://frilo.dev", "logo": "https://frilo.dev/logos/isotipo-oliva.png", "slogan": "Tus finanzas, mejor con Frilo", "areaServed": "CO" }, { "@type": "WebSite", "@id": "https://frilo.dev/#website", "url": "https://frilo.dev", "name": "Frilo", "inLanguage": "es-CO", "publisher": { "@id": "https://frilo.dev/#organization" } }, { "@type": "Person", "@id": "https://frilo.dev/#nicolas", "name": "Nicolás Suárez", "jobTitle": "Fundador de Frilo", "url": "https://frilo.dev/quienes-somos" }, { "@type": "WebPage", "@id": "https://frilo.dev/guias/cuenta-en-dolares-colombia", "url": "https://frilo.dev/guias/cuenta-en-dolares-colombia", "name": "Cuenta en dólares en Colombia: opciones, requisitos y costos", "description": "Compara las opciones para tener una cuenta en dólares en Colombia: requisitos, costos y tiempos de apertura. Guía para freelancers en 2026.", "inLanguage": "es-CO", "isPartOf": { "@id": "https://frilo.dev/#website" }, "dateModified": "2026-10-20", "reviewedBy": { "@type": "Organization", "name": "Equipo de finanzas Frilo", "parentOrganization": { "@id": "https://frilo.dev/#organization" } }, "lastReviewed": "2026-10-20", "mainEntity": { "@id": "https://frilo.dev/guias/cuenta-en-dolares-colombia#article" } }, { "@type": "Article", "@id": "https://frilo.dev/guias/cuenta-en-dolares-colombia#article", "headline": "Cuenta en dólares en Colombia: opciones, requisitos y costos", "description": "Compara las opciones para tener una cuenta en dólares en Colombia: requisitos, costos y tiempos de apertura. Guía para freelancers en 2026.", "mainEntityOfPage": "https://frilo.dev/guias/cuenta-en-dolares-colombia", "inLanguage": "es-CO", "author": { "@id": "https://frilo.dev/#nicolas" }, "publisher": { "@id": "https://frilo.dev/#organization" }, "datePublished": "2026-10-20", "dateModified": "2026-10-20", "image": "https://frilo.dev/og/guias/cuenta-en-dolares-colombia.png" }, { "@type": "BreadcrumbList", "itemListElement": [ { "@type": "ListItem", "position": 1, "name": "Inicio", "item": "https://frilo.dev" }, { "@type": "ListItem", "position": 2, "name": "Guías", "item": "https://frilo.dev/guias" }, { "@type": "ListItem", "position": 3, "name": "Cuenta en dólares" } ] }, { "@type": "FAQPage", "@id": "https://frilo.dev/guias/cuenta-en-dolares-colombia#faq", "mainEntity": [ { "@type": "Question", "name": "¿Un freelancer puede abrir una cuenta en dólares en Colombia?", "acceptedAnswer": { "@type": "Answer", "text": "Sí. Puedes abrirla en un banco con filial en el exterior o usar una plataforma digital. Revisa si la entidad está vigilada por la Superintendencia Financiera: algunas plataformas, como Littio, no lo están y no tienen el respaldo de Fogafín." } }, { "@type": "Question", "name": "¿Tengo que declarar una cuenta en dólares?", "acceptedAnswer": { "@type": "Answer", "text": "Los saldos y los ingresos en dólares se incluyen en tu declaración de renta. En lo cambiario, la DIAN explica que las operaciones de canalización obligatoria se hacen por intermediarios del mercado cambiario o por cuentas de compensación registradas en el Banco de la República, con declaración de cambio, y que debes guardar los soportes por cinco años. Revisa tu caso en la página de control cambiario de la DIAN." } }, { "@type": "Question", "name": "¿Cuánto cobran por recibir una transferencia en dólares?", "acceptedAnswer": { "@type": "Answer", "text": "Depende de la entidad. Por ejemplo, Littio cobra USD 2,99 por recibir desde EE. UU. o Europa (consultado el 20 de octubre de 2026). Además, al pasar a pesos se aplica la tasa de la entidad, no la TRM." } } ] } ] } | E11: Un solo script por página. Organization, WebSite y Person van en todas las páginas con el mismo @id. dateModified y lastReviewed = fecha real de la última edición (la misma visible en la página). FAQPage con las preguntas visibles del wireframe: si el texto cambia en el código, regenerar.
